2018-06-18 22:22:02,107 [Thread-1:14368] [django.server:124] [basehttp:log_message] [ERROR]- "POST /api/score/studentrank/ HTTP/1.1" 500 0
2018-06-18 22:22:20,984 [Thread-3:13796] [django.server:124] [basehttp:log_message] [ERROR]- "POST /api/score/studentrank/ HTTP/1.1" 500 0
2018-06-18 22:23:58,285 [Thread-1:2612] [django.server:124] [basehttp:log_message] [INFO]- "POST /api/score/studentrank/ HTTP/1.1" 200 8
2018-06-18 22:25:50,446 [Thread-1:3696] [django.server:124] [basehttp:log_message] [ERROR]- "POST /api/score/studentrank/ HTTP/1.1" 500 0
2018-06-18 22:26:14,285 [Thread-1:10452] [django.server:124] [basehttp:log_message] [INFO]- "POST /api/score/studentrank/ HTTP/1.1" 200 8
2018-06-18 22:26:25,585 [Thread-1:11364] [django.server:124] [basehttp:log_message] [ERROR]- "POST /api/score/studentrank/ HTTP/1.1" 500 0
2018-06-18 22:26:36,629 [Thread-1:13328] [django.server:124] [basehttp:log_message] [ERROR]- "POST /api/score/studentrank/ HTTP/1.1" 500 0
2018-06-18 22:28:31,625 [Thread-1:7736] [django.server:124] [basehttp:log_message] [ERROR]- "POST /api/score/studentrank/ HTTP/1.1" 500 0
2018-06-18 22:43:14,822 [Thread-1:2768] [django.server:124] [basehttp:log_message] [ERROR]- "POST /api/score/studentrank/ HTTP/1.1" 500 0
2018-06-18 22:55:37,744 [Thread-1:13564] [django.server:124] [basehttp:log_message] [ERROR]- "POST /api/score/studentrank/ HTTP/1.1" 500 0
2018-06-18 22:57:36,966 [Thread-1:15112] [django.server:124] [basehttp:log_message] [ERROR]- "POST /api/score/studentrank/ HTTP/1.1" 500 0
2018-06-18 22:58:13,011 [Thread-3:11084] [django.server:124] [basehttp:log_message] [ERROR]- "POST /api/score/studentrank/ HTTP/1.1" 500 0
2018-06-18 23:29:54,791 [Thread-1:8748] [django.server:124] [basehttp:log_message] [INFO]- "POST /api/score/studentrank/ HTTP/1.1" 200 11
2018-06-18 23:35:14,912 [Thread-1:11560] [django.request:93] [base:get_response] [WARNING]- Not Found: /api/score/updateupdatestudentrank/
2018-06-18 23:35:14,912 [Thread-1:11560] [django.server:124] [basehttp:log_message] [WARNING]- "POST /api/score/updateupdatestudentrank/ HTTP/1.1" 404 108
2018-06-18 23:35:33,735 [Thread-3:5492] [django.request:118] [exception:handle_uncaught_exception] [ERROR]- Internal Server Error: /api/score/updatestudentrank/
Traceback (most recent call last):
  File "C:\Users\Austin\PycharmProject\SE-TSS\venv\lib\site-packages\django\core\handlers\exception.py", line 35, in inner
    response = get_response(request)
  File "C:\Users\Austin\PycharmProject\SE-TSS\venv\lib\site-packages\django\core\handlers\base.py", line 128, in _get_response
    response = self.process_exception_by_middleware(e, request)
  File "C:\Users\Austin\PycharmProject\SE-TSS\venv\lib\site-packages\django\core\handlers\base.py", line 126, in _get_response
    response = wrapped_callback(request, *callback_args, **callback_kwargs)
  File "C:\Users\Austin\PycharmProject\SE-TSS\venv\lib\site-packages\django\views\decorators\csrf.py", line 54, in wrapped_view
    return view_func(*args, **kwargs)
  File "C:\Users\Austin\PycharmProject\SE-TSS\venv\lib\site-packages\django\views\generic\base.py", line 69, in view
    return self.dispatch(request, *args, **kwargs)
  File "C:\Users\Austin\PycharmProject\SE-TSS\venv\lib\site-packages\rest_framework\views.py", line 485, in dispatch
    self.response = self.finalize_response(request, response, *args, **kwargs)
  File "C:\Users\Austin\PycharmProject\SE-TSS\venv\lib\site-packages\rest_framework\views.py", line 400, in finalize_response
    % type(response)
AssertionError: Expected a `Response`, `HttpResponse` or `HttpStreamingResponse` to be returned from the view, but received a `<class 'NoneType'>`
2018-06-18 23:35:33,913 [Thread-3:5492] [django.server:124] [basehttp:log_message] [ERROR]- "POST /api/score/updatestudentrank/ HTTP/1.1" 500 27
2018-06-18 23:35:38,415 [Thread-4:15356] [django.request:118] [exception:handle_uncaught_exception] [ERROR]- Internal Server Error: /api/score/updatestudentrank/
Traceback (most recent call last):
  File "C:\Users\Austin\PycharmProject\SE-TSS\venv\lib\site-packages\django\core\handlers\exception.py", line 35, in inner
    response = get_response(request)
  File "C:\Users\Austin\PycharmProject\SE-TSS\venv\lib\site-packages\django\core\handlers\base.py", line 128, in _get_response
    response = self.process_exception_by_middleware(e, request)
  File "C:\Users\Austin\PycharmProject\SE-TSS\venv\lib\site-packages\django\core\handlers\base.py", line 126, in _get_response
    response = wrapped_callback(request, *callback_args, **callback_kwargs)
  File "C:\Users\Austin\PycharmProject\SE-TSS\venv\lib\site-packages\django\views\decorators\csrf.py", line 54, in wrapped_view
    return view_func(*args, **kwargs)
  File "C:\Users\Austin\PycharmProject\SE-TSS\venv\lib\site-packages\django\views\generic\base.py", line 69, in view
    return self.dispatch(request, *args, **kwargs)
  File "C:\Users\Austin\PycharmProject\SE-TSS\venv\lib\site-packages\rest_framework\views.py", line 485, in dispatch
    self.response = self.finalize_response(request, response, *args, **kwargs)
  File "C:\Users\Austin\PycharmProject\SE-TSS\venv\lib\site-packages\rest_framework\views.py", line 400, in finalize_response
    % type(response)
AssertionError: Expected a `Response`, `HttpResponse` or `HttpStreamingResponse` to be returned from the view, but received a `<class 'NoneType'>`
2018-06-18 23:35:38,417 [Thread-4:15356] [django.server:124] [basehttp:log_message] [ERROR]- "POST /api/score/updatestudentrank/ HTTP/1.1" 500 27
2018-06-18 23:36:32,538 [Thread-5:16104] [django.request:118] [exception:handle_uncaught_exception] [ERROR]- Internal Server Error: /api/score/updatestudentrank/
Traceback (most recent call last):
  File "C:\Users\Austin\PycharmProject\SE-TSS\venv\lib\site-packages\django\core\handlers\exception.py", line 35, in inner
    response = get_response(request)
  File "C:\Users\Austin\PycharmProject\SE-TSS\venv\lib\site-packages\django\core\handlers\base.py", line 128, in _get_response
    response = self.process_exception_by_middleware(e, request)
  File "C:\Users\Austin\PycharmProject\SE-TSS\venv\lib\site-packages\django\core\handlers\base.py", line 126, in _get_response
    response = wrapped_callback(request, *callback_args, **callback_kwargs)
  File "C:\Users\Austin\PycharmProject\SE-TSS\venv\lib\site-packages\django\views\decorators\csrf.py", line 54, in wrapped_view
    return view_func(*args, **kwargs)
  File "C:\Users\Austin\PycharmProject\SE-TSS\venv\lib\site-packages\django\views\generic\base.py", line 69, in view
    return self.dispatch(request, *args, **kwargs)
  File "C:\Users\Austin\PycharmProject\SE-TSS\venv\lib\site-packages\rest_framework\views.py", line 485, in dispatch
    self.response = self.finalize_response(request, response, *args, **kwargs)
  File "C:\Users\Austin\PycharmProject\SE-TSS\venv\lib\site-packages\rest_framework\views.py", line 400, in finalize_response
    % type(response)
AssertionError: Expected a `Response`, `HttpResponse` or `HttpStreamingResponse` to be returned from the view, but received a `<class 'NoneType'>`
2018-06-18 23:36:32,539 [Thread-5:16104] [django.server:124] [basehttp:log_message] [ERROR]- "POST /api/score/updatestudentrank/ HTTP/1.1" 500 27
2018-06-18 23:37:12,484 [Thread-1:4964] [django.server:124] [basehttp:log_message] [INFO]- "POST /api/score/updatestudentrank/ HTTP/1.1" 200 11
2018-06-18 23:37:48,827 [Thread-1:5256] [django.server:124] [basehttp:log_message] [INFO]- "POST /api/score/updatestudentrank/ HTTP/1.1" 200 11
2018-06-18 23:38:02,100 [Thread-1:7940] [django.request:118] [exception:handle_uncaught_exception] [ERROR]- Internal Server Error: /api/score/updatestudentrank/
Traceback (most recent call last):
  File "C:\Users\Austin\PycharmProject\SE-TSS\venv\lib\site-packages\django\core\handlers\exception.py", line 35, in inner
    response = get_response(request)
  File "C:\Users\Austin\PycharmProject\SE-TSS\venv\lib\site-packages\django\core\handlers\base.py", line 128, in _get_response
    response = self.process_exception_by_middleware(e, request)
  File "C:\Users\Austin\PycharmProject\SE-TSS\venv\lib\site-packages\django\core\handlers\base.py", line 126, in _get_response
    response = wrapped_callback(request, *callback_args, **callback_kwargs)
  File "C:\Users\Austin\PycharmProject\SE-TSS\venv\lib\site-packages\django\views\decorators\csrf.py", line 54, in wrapped_view
    return view_func(*args, **kwargs)
  File "C:\Users\Austin\PycharmProject\SE-TSS\venv\lib\site-packages\django\views\generic\base.py", line 69, in view
    return self.dispatch(request, *args, **kwargs)
  File "C:\Users\Austin\PycharmProject\SE-TSS\venv\lib\site-packages\rest_framework\views.py", line 485, in dispatch
    self.response = self.finalize_response(request, response, *args, **kwargs)
  File "C:\Users\Austin\PycharmProject\SE-TSS\venv\lib\site-packages\rest_framework\views.py", line 400, in finalize_response
    % type(response)
AssertionError: Expected a `Response`, `HttpResponse` or `HttpStreamingResponse` to be returned from the view, but received a `<class 'NoneType'>`
2018-06-18 23:38:02,106 [Thread-1:7940] [django.server:124] [basehttp:log_message] [ERROR]- "POST /api/score/updatestudentrank/ HTTP/1.1" 500 27
2018-06-18 23:38:22,177 [Thread-1:17040] [django.request:118] [exception:handle_uncaught_exception] [ERROR]- Internal Server Error: /api/score/updatestudentrank/
Traceback (most recent call last):
  File "C:\Users\Austin\PycharmProject\SE-TSS\venv\lib\site-packages\django\core\handlers\exception.py", line 35, in inner
    response = get_response(request)
  File "C:\Users\Austin\PycharmProject\SE-TSS\venv\lib\site-packages\django\core\handlers\base.py", line 128, in _get_response
    response = self.process_exception_by_middleware(e, request)
  File "C:\Users\Austin\PycharmProject\SE-TSS\venv\lib\site-packages\django\core\handlers\base.py", line 126, in _get_response
    response = wrapped_callback(request, *callback_args, **callback_kwargs)
  File "C:\Users\Austin\PycharmProject\SE-TSS\venv\lib\site-packages\django\views\decorators\csrf.py", line 54, in wrapped_view
    return view_func(*args, **kwargs)
  File "C:\Users\Austin\PycharmProject\SE-TSS\venv\lib\site-packages\django\views\generic\base.py", line 69, in view
    return self.dispatch(request, *args, **kwargs)
  File "C:\Users\Austin\PycharmProject\SE-TSS\venv\lib\site-packages\rest_framework\views.py", line 485, in dispatch
    self.response = self.finalize_response(request, response, *args, **kwargs)
  File "C:\Users\Austin\PycharmProject\SE-TSS\venv\lib\site-packages\rest_framework\views.py", line 400, in finalize_response
    % type(response)
AssertionError: Expected a `Response`, `HttpResponse` or `HttpStreamingResponse` to be returned from the view, but received a `<class 'NoneType'>`
2018-06-18 23:38:22,187 [Thread-1:17040] [django.server:124] [basehttp:log_message] [ERROR]- "POST /api/score/updatestudentrank/ HTTP/1.1" 500 27
2018-06-18 23:38:28,644 [Thread-1:11544] [django.request:118] [exception:handle_uncaught_exception] [ERROR]- Internal Server Error: /api/score/updatestudentrank/
Traceback (most recent call last):
  File "C:\Users\Austin\PycharmProject\SE-TSS\venv\lib\site-packages\django\core\handlers\exception.py", line 35, in inner
    response = get_response(request)
  File "C:\Users\Austin\PycharmProject\SE-TSS\venv\lib\site-packages\django\core\handlers\base.py", line 128, in _get_response
    response = self.process_exception_by_middleware(e, request)
  File "C:\Users\Austin\PycharmProject\SE-TSS\venv\lib\site-packages\django\core\handlers\base.py", line 126, in _get_response
    response = wrapped_callback(request, *callback_args, **callback_kwargs)
  File "C:\Users\Austin\PycharmProject\SE-TSS\venv\lib\site-packages\django\views\decorators\csrf.py", line 54, in wrapped_view
    return view_func(*args, **kwargs)
  File "C:\Users\Austin\PycharmProject\SE-TSS\venv\lib\site-packages\django\views\generic\base.py", line 69, in view
    return self.dispatch(request, *args, **kwargs)
  File "C:\Users\Austin\PycharmProject\SE-TSS\venv\lib\site-packages\rest_framework\views.py", line 485, in dispatch
    self.response = self.finalize_response(request, response, *args, **kwargs)
  File "C:\Users\Austin\PycharmProject\SE-TSS\venv\lib\site-packages\rest_framework\views.py", line 400, in finalize_response
    % type(response)
AssertionError: Expected a `Response`, `HttpResponse` or `HttpStreamingResponse` to be returned from the view, but received a `<class 'NoneType'>`
2018-06-18 23:38:28,650 [Thread-1:11544] [django.server:124] [basehttp:log_message] [ERROR]- "POST /api/score/updatestudentrank/ HTTP/1.1" 500 27
2018-06-18 23:40:27,802 [Thread-1:16252] [django.request:118] [exception:handle_uncaught_exception] [ERROR]- Internal Server Error: /api/score/updatestudentrank/
Traceback (most recent call last):
  File "C:\Users\Austin\PycharmProject\SE-TSS\venv\lib\site-packages\django\core\handlers\exception.py", line 35, in inner
    response = get_response(request)
  File "C:\Users\Austin\PycharmProject\SE-TSS\venv\lib\site-packages\django\core\handlers\base.py", line 128, in _get_response
    response = self.process_exception_by_middleware(e, request)
  File "C:\Users\Austin\PycharmProject\SE-TSS\venv\lib\site-packages\django\core\handlers\base.py", line 126, in _get_response
    response = wrapped_callback(request, *callback_args, **callback_kwargs)
  File "C:\Users\Austin\PycharmProject\SE-TSS\venv\lib\site-packages\django\views\decorators\csrf.py", line 54, in wrapped_view
    return view_func(*args, **kwargs)
  File "C:\Users\Austin\PycharmProject\SE-TSS\venv\lib\site-packages\django\views\generic\base.py", line 69, in view
    return self.dispatch(request, *args, **kwargs)
  File "C:\Users\Austin\PycharmProject\SE-TSS\venv\lib\site-packages\rest_framework\views.py", line 485, in dispatch
    self.response = self.finalize_response(request, response, *args, **kwargs)
  File "C:\Users\Austin\PycharmProject\SE-TSS\venv\lib\site-packages\rest_framework\views.py", line 400, in finalize_response
    % type(response)
AssertionError: Expected a `Response`, `HttpResponse` or `HttpStreamingResponse` to be returned from the view, but received a `<class 'NoneType'>`
2018-06-18 23:40:27,809 [Thread-1:16252] [django.server:124] [basehttp:log_message] [ERROR]- "POST /api/score/updatestudentrank/ HTTP/1.1" 500 27
2018-06-18 23:40:40,803 [Thread-1:17036] [django.request:118] [exception:handle_uncaught_exception] [ERROR]- Internal Server Error: /api/score/updatestudentrank/
Traceback (most recent call last):
  File "C:\Users\Austin\PycharmProject\SE-TSS\venv\lib\site-packages\django\core\handlers\exception.py", line 35, in inner
    response = get_response(request)
  File "C:\Users\Austin\PycharmProject\SE-TSS\venv\lib\site-packages\django\core\handlers\base.py", line 128, in _get_response
    response = self.process_exception_by_middleware(e, request)
  File "C:\Users\Austin\PycharmProject\SE-TSS\venv\lib\site-packages\django\core\handlers\base.py", line 126, in _get_response
    response = wrapped_callback(request, *callback_args, **callback_kwargs)
  File "C:\Users\Austin\PycharmProject\SE-TSS\venv\lib\site-packages\django\views\decorators\csrf.py", line 54, in wrapped_view
    return view_func(*args, **kwargs)
  File "C:\Users\Austin\PycharmProject\SE-TSS\venv\lib\site-packages\django\views\generic\base.py", line 69, in view
    return self.dispatch(request, *args, **kwargs)
  File "C:\Users\Austin\PycharmProject\SE-TSS\venv\lib\site-packages\rest_framework\views.py", line 485, in dispatch
    self.response = self.finalize_response(request, response, *args, **kwargs)
  File "C:\Users\Austin\PycharmProject\SE-TSS\venv\lib\site-packages\rest_framework\views.py", line 400, in finalize_response
    % type(response)
AssertionError: Expected a `Response`, `HttpResponse` or `HttpStreamingResponse` to be returned from the view, but received a `<class 'NoneType'>`
2018-06-18 23:40:40,809 [Thread-1:17036] [django.server:124] [basehttp:log_message] [ERROR]- "POST /api/score/updatestudentrank/ HTTP/1.1" 500 27
2018-06-18 23:49:14,518 [Thread-1:8120] [django.server:124] [basehttp:log_message] [ERROR]- "POST /api/score/updatestudentrank/ HTTP/1.1" 500 0
2018-06-18 23:49:17,258 [Thread-3:9592] [django.server:124] [basehttp:log_message] [ERROR]- "POST /api/score/updatestudentrank/ HTTP/1.1" 500 0
2018-06-18 23:49:23,590 [Thread-4:9872] [django.server:124] [basehttp:log_message] [ERROR]- "POST /api/score/updatestudentrank/ HTTP/1.1" 500 0
2018-06-18 23:51:17,664 [Thread-1:7592] [django.request:118] [exception:handle_uncaught_exception] [ERROR]- Internal Server Error: /api/score/updatestudentrank/
Traceback (most recent call last):
  File "C:\Users\Austin\PycharmProject\SE-TSS\backend\score_management\views.py", line 293, in update_student_rank
    counts[id_number] += 1
KeyError: '000000000000000000'

During handling of the above exception, another exception occurred:

Traceback (most recent call last):
  File "C:\Users\Austin\PycharmProject\SE-TSS\venv\lib\site-packages\django\core\handlers\exception.py", line 35, in inner
    response = get_response(request)
  File "C:\Users\Austin\PycharmProject\SE-TSS\venv\lib\site-packages\django\core\handlers\base.py", line 128, in _get_response
    response = self.process_exception_by_middleware(e, request)
  File "C:\Users\Austin\PycharmProject\SE-TSS\venv\lib\site-packages\django\core\handlers\base.py", line 126, in _get_response
    response = wrapped_callback(request, *callback_args, **callback_kwargs)
  File "C:\Users\Austin\PycharmProject\SE-TSS\venv\lib\site-packages\django\views\decorators\csrf.py", line 54, in wrapped_view
    return view_func(*args, **kwargs)
  File "C:\Users\Austin\PycharmProject\SE-TSS\venv\lib\site-packages\django\views\generic\base.py", line 69, in view
    return self.dispatch(request, *args, **kwargs)
  File "C:\Users\Austin\PycharmProject\SE-TSS\venv\lib\site-packages\rest_framework\views.py", line 483, in dispatch
    response = self.handle_exception(exc)
  File "C:\Users\Austin\PycharmProject\SE-TSS\venv\lib\site-packages\rest_framework\views.py", line 443, in handle_exception
    self.raise_uncaught_exception(exc)
  File "C:\Users\Austin\PycharmProject\SE-TSS\venv\lib\site-packages\rest_framework\views.py", line 480, in dispatch
    response = handler(request, *args, **kwargs)
  File "C:\Users\Austin\PycharmProject\SE-TSS\venv\lib\site-packages\rest_framework\decorators.py", line 53, in handler
    return func(*args, **kwargs)
  File "C:\Users\Austin\PycharmProject\SE-TSS\backend\score_management\views.py", line 310, in update_student_rank
    print("Unexpected error:", sys.exc_info()[0])
NameError: name 'sys' is not defined
2018-06-18 23:51:17,692 [Thread-1:7592] [django.server:124] [basehttp:log_message] [ERROR]- "POST /api/score/updatestudentrank/ HTTP/1.1" 500 27
2018-06-18 23:52:29,395 [Thread-10:5492] [django.request:118] [exception:handle_uncaught_exception] [ERROR]- Internal Server Error: /api/score/updatestudentrank/
Traceback (most recent call last):
  File "C:\Users\Austin\PycharmProject\SE-TSS\backend\score_management\views.py", line 293, in update_student_rank
    counts[id_number] += 1
KeyError: '000000000000000000'

During handling of the above exception, another exception occurred:

Traceback (most recent call last):
  File "C:\Users\Austin\PycharmProject\SE-TSS\venv\lib\site-packages\django\core\handlers\exception.py", line 35, in inner
    response = get_response(request)
  File "C:\Users\Austin\PycharmProject\SE-TSS\venv\lib\site-packages\django\core\handlers\base.py", line 128, in _get_response
    response = self.process_exception_by_middleware(e, request)
  File "C:\Users\Austin\PycharmProject\SE-TSS\venv\lib\site-packages\django\core\handlers\base.py", line 126, in _get_response
    response = wrapped_callback(request, *callback_args, **callback_kwargs)
  File "C:\Users\Austin\PycharmProject\SE-TSS\venv\lib\site-packages\django\views\decorators\csrf.py", line 54, in wrapped_view
    return view_func(*args, **kwargs)
  File "C:\Users\Austin\PycharmProject\SE-TSS\venv\lib\site-packages\django\views\generic\base.py", line 69, in view
    return self.dispatch(request, *args, **kwargs)
  File "C:\Users\Austin\PycharmProject\SE-TSS\venv\lib\site-packages\rest_framework\views.py", line 483, in dispatch
    response = self.handle_exception(exc)
  File "C:\Users\Austin\PycharmProject\SE-TSS\venv\lib\site-packages\rest_framework\views.py", line 443, in handle_exception
    self.raise_uncaught_exception(exc)
  File "C:\Users\Austin\PycharmProject\SE-TSS\venv\lib\site-packages\rest_framework\views.py", line 480, in dispatch
    response = handler(request, *args, **kwargs)
  File "C:\Users\Austin\PycharmProject\SE-TSS\venv\lib\site-packages\rest_framework\decorators.py", line 53, in handler
    return func(*args, **kwargs)
  File "C:\Users\Austin\PycharmProject\SE-TSS\backend\score_management\views.py", line 310, in update_student_rank
    print("Unexpected error:", sys.exc_info()[0])
NameError: name 'sys' is not defined
2018-06-18 23:52:29,419 [Thread-10:5492] [django.server:124] [basehttp:log_message] [ERROR]- "POST /api/score/updatestudentrank/ HTTP/1.1" 500 27
2018-06-18 23:55:48,994 [Thread-1:2596] [django.request:118] [exception:handle_uncaught_exception] [ERROR]- Internal Server Error: /api/score/updatestudentrank/
Traceback (most recent call last):
  File "C:\Users\Austin\PycharmProject\SE-TSS\backend\score_management\views.py", line 293, in update_student_rank
    counts[id_number] += 1
KeyError: '000000000000000000'

During handling of the above exception, another exception occurred:

Traceback (most recent call last):
  File "C:\Users\Austin\PycharmProject\SE-TSS\venv\lib\site-packages\django\core\handlers\exception.py", line 35, in inner
    response = get_response(request)
  File "C:\Users\Austin\PycharmProject\SE-TSS\venv\lib\site-packages\django\core\handlers\base.py", line 128, in _get_response
    response = self.process_exception_by_middleware(e, request)
  File "C:\Users\Austin\PycharmProject\SE-TSS\venv\lib\site-packages\django\core\handlers\base.py", line 126, in _get_response
    response = wrapped_callback(request, *callback_args, **callback_kwargs)
  File "C:\Users\Austin\PycharmProject\SE-TSS\venv\lib\site-packages\django\views\decorators\csrf.py", line 54, in wrapped_view
    return view_func(*args, **kwargs)
  File "C:\Users\Austin\PycharmProject\SE-TSS\venv\lib\site-packages\django\views\generic\base.py", line 69, in view
    return self.dispatch(request, *args, **kwargs)
  File "C:\Users\Austin\PycharmProject\SE-TSS\venv\lib\site-packages\rest_framework\views.py", line 483, in dispatch
    response = self.handle_exception(exc)
  File "C:\Users\Austin\PycharmProject\SE-TSS\venv\lib\site-packages\rest_framework\views.py", line 443, in handle_exception
    self.raise_uncaught_exception(exc)
  File "C:\Users\Austin\PycharmProject\SE-TSS\venv\lib\site-packages\rest_framework\views.py", line 480, in dispatch
    response = handler(request, *args, **kwargs)
  File "C:\Users\Austin\PycharmProject\SE-TSS\venv\lib\site-packages\rest_framework\decorators.py", line 53, in handler
    return func(*args, **kwargs)
  File "C:\Users\Austin\PycharmProject\SE-TSS\backend\score_management\views.py", line 310, in update_student_rank
    print("Unexpected error:", sys.exc_info()[0])
NameError: name 'sys' is not defined
2018-06-18 23:55:49,001 [Thread-1:2596] [django.server:124] [basehttp:log_message] [ERROR]- "POST /api/score/updatestudentrank/ HTTP/1.1" 500 27
2018-06-18 23:56:16,732 [Thread-1:2428] [django.server:124] [basehttp:log_message] [INFO]- "POST /api/score/updatestudentrank/ HTTP/1.1" 200 11
2018-06-18 23:56:31,602 [Thread-1:10336] [django.request:118] [exception:handle_uncaught_exception] [ERROR]- Internal Server Error: /api/score/updatestudentrank/
Traceback (most recent call last):
  File "C:\Users\Austin\PycharmProject\SE-TSS\backend\score_management\views.py", line 293, in update_student_rank
    counts[id_number] += 1
KeyError: '000000000000000000'

During handling of the above exception, another exception occurred:

Traceback (most recent call last):
  File "C:\Users\Austin\PycharmProject\SE-TSS\venv\lib\site-packages\django\core\handlers\exception.py", line 35, in inner
    response = get_response(request)
  File "C:\Users\Austin\PycharmProject\SE-TSS\venv\lib\site-packages\django\core\handlers\base.py", line 128, in _get_response
    response = self.process_exception_by_middleware(e, request)
  File "C:\Users\Austin\PycharmProject\SE-TSS\venv\lib\site-packages\django\core\handlers\base.py", line 126, in _get_response
    response = wrapped_callback(request, *callback_args, **callback_kwargs)
  File "C:\Users\Austin\PycharmProject\SE-TSS\venv\lib\site-packages\django\views\decorators\csrf.py", line 54, in wrapped_view
    return view_func(*args, **kwargs)
  File "C:\Users\Austin\PycharmProject\SE-TSS\venv\lib\site-packages\django\views\generic\base.py", line 69, in view
    return self.dispatch(request, *args, **kwargs)
  File "C:\Users\Austin\PycharmProject\SE-TSS\venv\lib\site-packages\rest_framework\views.py", line 483, in dispatch
    response = self.handle_exception(exc)
  File "C:\Users\Austin\PycharmProject\SE-TSS\venv\lib\site-packages\rest_framework\views.py", line 443, in handle_exception
    self.raise_uncaught_exception(exc)
  File "C:\Users\Austin\PycharmProject\SE-TSS\venv\lib\site-packages\rest_framework\views.py", line 480, in dispatch
    response = handler(request, *args, **kwargs)
  File "C:\Users\Austin\PycharmProject\SE-TSS\venv\lib\site-packages\rest_framework\decorators.py", line 53, in handler
    return func(*args, **kwargs)
  File "C:\Users\Austin\PycharmProject\SE-TSS\backend\score_management\views.py", line 310, in update_student_rank
    print("Unexpected error:", sys.exc_info()[0])
NameError: name 'sys' is not defined
2018-06-18 23:56:31,609 [Thread-1:10336] [django.server:124] [basehttp:log_message] [ERROR]- "POST /api/score/updatestudentrank/ HTTP/1.1" 500 27
2018-06-18 23:56:51,378 [Thread-1:15716] [django.server:124] [basehttp:log_message] [INFO]- "POST /api/score/updatestudentrank/ HTTP/1.1" 200 11
2018-06-18 23:57:32,775 [Thread-1:6656] [django.request:118] [exception:handle_uncaught_exception] [ERROR]- Internal Server Error: /api/score/updatestudentrank/
Traceback (most recent call last):
  File "C:\Users\Austin\PycharmProject\SE-TSS\backend\score_management\views.py", line 294, in update_student_rank
    counts[id_number] += 1
KeyError: '000000000000000000'

During handling of the above exception, another exception occurred:

Traceback (most recent call last):
  File "C:\Users\Austin\PycharmProject\SE-TSS\venv\lib\site-packages\django\core\handlers\exception.py", line 35, in inner
    response = get_response(request)
  File "C:\Users\Austin\PycharmProject\SE-TSS\venv\lib\site-packages\django\core\handlers\base.py", line 128, in _get_response
    response = self.process_exception_by_middleware(e, request)
  File "C:\Users\Austin\PycharmProject\SE-TSS\venv\lib\site-packages\django\core\handlers\base.py", line 126, in _get_response
    response = wrapped_callback(request, *callback_args, **callback_kwargs)
  File "C:\Users\Austin\PycharmProject\SE-TSS\venv\lib\site-packages\django\views\decorators\csrf.py", line 54, in wrapped_view
    return view_func(*args, **kwargs)
  File "C:\Users\Austin\PycharmProject\SE-TSS\venv\lib\site-packages\django\views\generic\base.py", line 69, in view
    return self.dispatch(request, *args, **kwargs)
  File "C:\Users\Austin\PycharmProject\SE-TSS\venv\lib\site-packages\rest_framework\views.py", line 483, in dispatch
    response = self.handle_exception(exc)
  File "C:\Users\Austin\PycharmProject\SE-TSS\venv\lib\site-packages\rest_framework\views.py", line 443, in handle_exception
    self.raise_uncaught_exception(exc)
  File "C:\Users\Austin\PycharmProject\SE-TSS\venv\lib\site-packages\rest_framework\views.py", line 480, in dispatch
    response = handler(request, *args, **kwargs)
  File "C:\Users\Austin\PycharmProject\SE-TSS\venv\lib\site-packages\rest_framework\decorators.py", line 53, in handler
    return func(*args, **kwargs)
  File "C:\Users\Austin\PycharmProject\SE-TSS\backend\score_management\views.py", line 310, in update_student_rank
    print("Unexpected error:", sys.exc_info()[0])
NameError: name 'sys' is not defined
2018-06-18 23:57:32,783 [Thread-1:6656] [django.server:124] [basehttp:log_message] [ERROR]- "POST /api/score/updatestudentrank/ HTTP/1.1" 500 27
2018-06-18 23:57:45,992 [Thread-1:16676] [django.server:124] [basehttp:log_message] [INFO]- "POST /api/score/updatestudentrank/ HTTP/1.1" 200 11
2018-06-18 23:58:11,296 [Thread-1:15732] [django.request:118] [exception:handle_uncaught_exception] [ERROR]- Internal Server Error: /api/score/updatestudentrank/
Traceback (most recent call last):
  File "C:\Users\Austin\PycharmProject\SE-TSS\backend\score_management\views.py", line 294, in update_student_rank
    counts[id_number] += 1
KeyError: '000000000000000000'

During handling of the above exception, another exception occurred:

Traceback (most recent call last):
  File "C:\Users\Austin\PycharmProject\SE-TSS\venv\lib\site-packages\django\core\handlers\exception.py", line 35, in inner
    response = get_response(request)
  File "C:\Users\Austin\PycharmProject\SE-TSS\venv\lib\site-packages\django\core\handlers\base.py", line 128, in _get_response
    response = self.process_exception_by_middleware(e, request)
  File "C:\Users\Austin\PycharmProject\SE-TSS\venv\lib\site-packages\django\core\handlers\base.py", line 126, in _get_response
    response = wrapped_callback(request, *callback_args, **callback_kwargs)
  File "C:\Users\Austin\PycharmProject\SE-TSS\venv\lib\site-packages\django\views\decorators\csrf.py", line 54, in wrapped_view
    return view_func(*args, **kwargs)
  File "C:\Users\Austin\PycharmProject\SE-TSS\venv\lib\site-packages\django\views\generic\base.py", line 69, in view
    return self.dispatch(request, *args, **kwargs)
  File "C:\Users\Austin\PycharmProject\SE-TSS\venv\lib\site-packages\rest_framework\views.py", line 483, in dispatch
    response = self.handle_exception(exc)
  File "C:\Users\Austin\PycharmProject\SE-TSS\venv\lib\site-packages\rest_framework\views.py", line 443, in handle_exception
    self.raise_uncaught_exception(exc)
  File "C:\Users\Austin\PycharmProject\SE-TSS\venv\lib\site-packages\rest_framework\views.py", line 480, in dispatch
    response = handler(request, *args, **kwargs)
  File "C:\Users\Austin\PycharmProject\SE-TSS\venv\lib\site-packages\rest_framework\decorators.py", line 53, in handler
    return func(*args, **kwargs)
  File "C:\Users\Austin\PycharmProject\SE-TSS\backend\score_management\views.py", line 311, in update_student_rank
    print("Unexpected error:", sys.exc_info()[0])
NameError: name 'sys' is not defined
2018-06-18 23:58:11,304 [Thread-1:15732] [django.server:124] [basehttp:log_message] [ERROR]- "POST /api/score/updatestudentrank/ HTTP/1.1" 500 27
2018-06-18 23:59:09,781 [Thread-1:11336] [django.server:124] [basehttp:log_message] [INFO]- "POST /api/score/updatestudentrank/ HTTP/1.1" 200 11
2018-06-19 00:01:30,834 [Thread-1:16848] [django.server:124] [basehttp:log_message] [INFO]- "POST /api/score/updatestudentrank/ HTTP/1.1" 200 11
2018-06-19 00:02:10,862 [Thread-1:16416] [django.server:124] [basehttp:log_message] [INFO]- "POST /api/score/updatestudentrank/ HTTP/1.1" 200 11
2018-06-19 00:02:39,773 [Thread-1:7456] [django.server:124] [basehttp:log_message] [ERROR]- "POST /api/score/updatestudentrank/ HTTP/1.1" 500 0
2018-06-19 00:04:14,026 [Thread-1:16100] [django.server:124] [basehttp:log_message] [ERROR]- "POST /api/score/updatestudentrank/ HTTP/1.1" 500 0
2018-06-19 00:06:21,447 [Thread-1:12420] [django.server:124] [basehttp:log_message] [ERROR]- "POST /api/score/updatestudentrank/ HTTP/1.1" 500 0
2018-06-19 00:07:06,199 [Thread-1:15872] [django.server:124] [basehttp:log_message] [INFO]- "POST /api/score/updatestudentrank/ HTTP/1.1" 200 11
2018-06-19 00:07:23,792 [Thread-1:16656] [django.server:124] [basehttp:log_message] [INFO]- "POST /api/score/updatestudentrank/ HTTP/1.1" 200 11
2018-06-19 00:07:42,043 [Thread-1:5736] [django.server:124] [basehttp:log_message] [ERROR]- "POST /api/score/updatestudentrank/ HTTP/1.1" 500 0
2018-06-19 00:45:11,539 [Thread-1:16572] [django.server:124] [basehttp:log_message] [ERROR]- "POST /api/score/updatestudentrank/ HTTP/1.1" 500 0
2018-06-19 00:47:47,075 [Thread-1:12884] [django.server:124] [basehttp:log_message] [ERROR]- "POST /api/score/updatestudentrank/ HTTP/1.1" 500 0
2018-06-19 00:48:56,627 [Thread-1:2428] [django.server:124] [basehttp:log_message] [ERROR]- "POST /api/score/updatestudentrank/ HTTP/1.1" 500 0
2018-06-19 00:52:19,873 [Thread-1:1612] [django.server:124] [basehttp:log_message] [ERROR]- "POST /api/score/updatestudentrank/ HTTP/1.1" 500 0
2018-06-19 00:52:55,256 [Thread-1:13944] [django.server:124] [basehttp:log_message] [ERROR]- "POST /api/score/updatestudentrank/ HTTP/1.1" 500 0
2018-06-19 01:03:20,330 [Thread-1:1192] [django.server:124] [basehttp:log_message] [ERROR]- "POST /api/score/updatestudentrank/ HTTP/1.1" 500 0
2018-06-19 01:20:24,775 [Thread-1:10612] [django.server:124] [basehttp:log_message] [ERROR]- "POST /api/score/updatestudentrank/ HTTP/1.1" 500 0
2018-06-19 01:20:50,716 [Thread-1:12648] [django.server:124] [basehttp:log_message] [ERROR]- "POST /api/score/updatestudentrank/ HTTP/1.1" 500 0
2018-06-19 01:23:34,291 [Thread-1:13664] [django.server:124] [basehttp:log_message] [ERROR]- "POST /api/score/updatestudentrank/ HTTP/1.1" 500 0
2018-06-19 01:24:01,708 [Thread-1:8084] [django.server:124] [basehttp:log_message] [ERROR]- "POST /api/score/updatestudentrank/ HTTP/1.1" 500 0
2018-06-19 01:24:31,897 [Thread-1:12352] [django.server:124] [basehttp:log_message] [ERROR]- "POST /api/score/updatestudentrank/ HTTP/1.1" 500 0
2018-06-19 01:24:44,640 [Thread-1:15396] [django.server:124] [basehttp:log_message] [ERROR]- "POST /api/score/updatestudentrank/ HTTP/1.1" 500 0
2018-06-19 01:25:30,570 [Thread-1:12984] [django.server:124] [basehttp:log_message] [ERROR]- "POST /api/score/updatestudentrank/ HTTP/1.1" 500 0
2018-06-19 01:26:12,678 [Thread-1:12832] [django.server:124] [basehttp:log_message] [ERROR]- "POST /api/score/updatestudentrank/ HTTP/1.1" 500 0
2018-06-19 01:26:33,140 [Thread-1:16316] [django.server:124] [basehttp:log_message] [ERROR]- "POST /api/score/updatestudentrank/ HTTP/1.1" 500 0
2018-06-19 01:27:24,985 [Thread-1:17160] [django.server:124] [basehttp:log_message] [ERROR]- "POST /api/score/updatestudentrank/ HTTP/1.1" 500 0
2018-06-19 01:32:39,486 [Thread-1:13672] [django.server:124] [basehttp:log_message] [ERROR]- "POST /api/score/updatestudentrank/ HTTP/1.1" 500 0
2018-06-19 01:43:57,672 [Thread-1:11164] [django.server:124] [basehttp:log_message] [INFO]- "POST /api/score/updatestudentrank/ HTTP/1.1" 200 0
2018-06-19 01:44:25,560 [Thread-3:6140] [django.server:124] [basehttp:log_message] [INFO]- "POST /api/score/updatestudentrank/ HTTP/1.1" 200 0
2018-06-19 01:44:42,363 [Thread-4:808] [django.server:124] [basehttp:log_message] [INFO]- "POST /api/score/updatestudentrank/ HTTP/1.1" 200 0
2018-06-19 01:45:09,629 [Thread-5:4972] [django.server:124] [basehttp:log_message] [INFO]- "POST /api/score/updatestudentrank/ HTTP/1.1" 200 0
2018-06-19 01:45:16,131 [Thread-1:15692] [django.server:124] [basehttp:log_message] [INFO]- "POST /api/score/updatestudentrank/ HTTP/1.1" 200 0
2018-06-19 01:46:17,561 [Thread-1:7392] [django.server:124] [basehttp:log_message] [INFO]- "POST /api/score/updatestudentrank/ HTTP/1.1" 200 0
2018-06-19 01:47:01,740 [Thread-1:16824] [django.server:124] [basehttp:log_message] [INFO]- "POST /api/score/updatestudentrank/ HTTP/1.1" 200 11
2018-06-19 01:58:41,710 [Thread-1:9452] [django.server:124] [basehttp:log_message] [INFO]- "POST /api/score/updatestudentrank/ HTTP/1.1" 200 0
2018-06-19 01:59:56,804 [Thread-3:12080] [django.server:124] [basehttp:log_message] [ERROR]- "POST /api/score/studentrank/ HTTP/1.1" 500 0
2018-06-19 02:00:49,271 [Thread-1:8144] [django.server:124] [basehttp:log_message] [INFO]- "POST /api/score/studentrank/ HTTP/1.1" 200 11
2018-06-19 02:02:51,409 [Thread-3:14128] [django.server:124] [basehttp:log_message] [ERROR]- "POST /api/score/updatestudentrank/ HTTP/1.1" 500 0
2018-06-19 02:09:40,452 [Thread-1:13088] [django.server:124] [basehttp:log_message] [INFO]- "POST /api/score/updatestudentrank/ HTTP/1.1" 200 0
2018-06-19 02:11:08,404 [Thread-1:4972] [django.server:124] [basehttp:log_message] [INFO]- "POST /api/score/updatestudentrank/ HTTP/1.1" 200 0
2018-06-19 02:13:11,919 [Thread-1:7660] [django.server:124] [basehttp:log_message] [INFO]- "POST /api/score/updatestudentrank/ HTTP/1.1" 200 0
2018-06-20 23:18:14,470 [Thread-1:8656] [django.server:124] [basehttp:log_message] [INFO]- "POST /api/score/listallscore/ HTTP/1.1" 200 57
2018-06-20 23:27:42,505 [Thread-1:2536] [django.server:124] [basehttp:log_message] [INFO]- "POST /api/score/listallscore/ HTTP/1.1" 200 57
2018-06-20 23:29:49,946 [Thread-3:9480] [django.server:124] [basehttp:log_message] [ERROR]- "POST /api/score/listallscore/ HTTP/1.1" 500 0
2018-06-20 23:29:53,445 [Thread-4:380] [django.server:124] [basehttp:log_message] [ERROR]- "POST /api/score/listallscore/ HTTP/1.1" 500 0
2018-06-20 23:30:06,038 [Thread-1:10568] [django.server:124] [basehttp:log_message] [ERROR]- "POST /api/score/listallscore/ HTTP/1.1" 500 0
2018-06-20 23:33:10,047 [Thread-1:14816] [django.server:124] [basehttp:log_message] [INFO]- "POST /api/score/listallscore/ HTTP/1.1" 200 199
2018-06-20 23:36:50,260 [Thread-3:4196] [django.server:124] [basehttp:log_message] [INFO]- "POST /api/score/listallscore/ HTTP/1.1" 200 205
2018-06-20 23:38:55,133 [Thread-4:1080] [django.request:93] [base:get_response] [WARNING]- Not Found: /api/score/updaterank/
2018-06-20 23:38:55,133 [Thread-4:1080] [django.server:124] [basehttp:log_message] [WARNING]- "POST /api/score/updaterank/ HTTP/1.1" 404 4317
